[33mWARNING[0m:  [19-05-2024 17:41:36] chroma_server_nofile is not supported on Windows. chroma_server_nofile will not be set.
[32mINFO[0m:     [19-05-2024 17:41:37] Anonymized telemetry enabled. See                     https://docs.trychroma.com/telemetry for more information.
[36mDEBUG[0m:    [19-05-2024 17:41:37] Starting component System
[36mDEBUG[0m:    [19-05-2024 17:41:37] Starting component OpenTelemetryClient
[36mDEBUG[0m:    [19-05-2024 17:41:37] Starting component SqliteDB
[36mDEBUG[0m:    [19-05-2024 17:41:37] Starting component QuotaEnforcer
[36mDEBUG[0m:    [19-05-2024 17:41:37] Starting component Posthog
[36mDEBUG[0m:    [19-05-2024 17:41:37] Starting component LocalSegmentManager
[36mDEBUG[0m:    [19-05-2024 17:41:37] Starting component SegmentAPI
[32mINFO[0m:     [19-05-2024 17:41:37] Started server process [[36m2708[0m]
[32mINFO[0m:     [19-05-2024 17:41:37] Waiting for application startup.
[32mINFO[0m:     [19-05-2024 17:41:37] Application startup complete.
[32mINFO[0m:     [19-05-2024 17:41:37] Uvicorn running on [1mhttp://localhost:8000[0m (Press CTRL+C to quit)
[32mINFO[0m:     [19-05-2024 17:42:05] ::1:61938 - "GET /api/v1/tenants/default_tenant HTTP/1.1" 200
[32mINFO[0m:     [19-05-2024 17:42:05] ::1:61938 - "GET /api/v1/databases/default_database?tenant=default_tenant HTTP/1.1" 200
[32mINFO[0m:     [19-05-2024 17:43:34] ::1:61971 - "GET /api/v1/tenants/default_tenant HTTP/1.1" 200
[32mINFO[0m:     [19-05-2024 17:43:34] ::1:61971 - "GET /api/v1/databases/default_database?tenant=default_tenant HTTP/1.1" 200
[31mERROR[0m:    [19-05-2024 17:43:36] Collection docs_collection does not exist.
Traceback (most recent call last):
  File "C:\Users\kaarelso\AppData\Local\anaconda3\envs\ut-rag\Lib\site-packages\anyio\streams\memory.py", line 97, in receive
    return self.receive_nowait()
           ^^^^^^^^^^^^^^^^^^^^^
  File "C:\Users\kaarelso\AppData\Local\anaconda3\envs\ut-rag\Lib\site-packages\anyio\streams\memory.py", line 92, in receive_nowait
    raise WouldBlock
anyio.WouldBlock

During handling of the above exception, another exception occurred:

Traceback (most recent call last):
  File "C:\Users\kaarelso\AppData\Local\anaconda3\envs\ut-rag\Lib\site-packages\starlette\middleware\base.py", line 159, in call_next
    message = await recv_stream.receive()
              ^^^^^^^^^^^^^^^^^^^^^^^^^^^
  File "C:\Users\kaarelso\AppData\Local\anaconda3\envs\ut-rag\Lib\site-packages\anyio\streams\memory.py", line 112, in receive
    raise EndOfStream
anyio.EndOfStream

During handling of the above exception, another exception occurred:

Traceback (most recent call last):
  File "C:\Users\kaarelso\AppData\Local\anaconda3\envs\ut-rag\Lib\site-packages\chromadb\server\fastapi\__init__.py", line 78, in catch_exceptions_middleware
    return await call_next(request)
           ^^^^^^^^^^^^^^^^^^^^^^^^
  File "C:\Users\kaarelso\AppData\Local\anaconda3\envs\ut-rag\Lib\site-packages\starlette\middleware\base.py", line 165, in call_next
    raise app_exc
  File "C:\Users\kaarelso\AppData\Local\anaconda3\envs\ut-rag\Lib\site-packages\starlette\middleware\base.py", line 151, in coro
    await self.app(scope, receive_or_disconnect, send_no_error)
  File "C:\Users\kaarelso\AppData\Local\anaconda3\envs\ut-rag\Lib\site-packages\starlette\middleware\base.py", line 189, in __call__
    with collapse_excgroups():
  File "C:\Users\kaarelso\AppData\Local\anaconda3\envs\ut-rag\Lib\contextlib.py", line 158, in __exit__
    self.gen.throw(typ, value, traceback)
  File "C:\Users\kaarelso\AppData\Local\anaconda3\envs\ut-rag\Lib\site-packages\starlette\_utils.py", line 93, in collapse_excgroups
    raise exc
  File "C:\Users\kaarelso\AppData\Local\anaconda3\envs\ut-rag\Lib\site-packages\starlette\middleware\base.py", line 191, in __call__
    response = await self.dispatch_func(request, call_next)
               ^^^^^^^^^^^^^^^^^^^^^^^^^^^^^^^^^^^^^^^^^^^^
  File "C:\Users\kaarelso\AppData\Local\anaconda3\envs\ut-rag\Lib\site-packages\chromadb\server\fastapi\__init__.py", line 92, in check_http_version_middleware
    return await call_next(request)
           ^^^^^^^^^^^^^^^^^^^^^^^^
  File "C:\Users\kaarelso\AppData\Local\anaconda3\envs\ut-rag\Lib\site-packages\starlette\middleware\base.py", line 165, in call_next
    raise app_exc
  File "C:\Users\kaarelso\AppData\Local\anaconda3\envs\ut-rag\Lib\site-packages\starlette\middleware\base.py", line 151, in coro
    await self.app(scope, receive_or_disconnect, send_no_error)
  File "C:\Users\kaarelso\AppData\Local\anaconda3\envs\ut-rag\Lib\site-packages\starlette\middleware\exceptions.py", line 65, in __call__
    await wrap_app_handling_exceptions(self.app, conn)(scope, receive, send)
  File "C:\Users\kaarelso\AppData\Local\anaconda3\envs\ut-rag\Lib\site-packages\starlette\_exception_handler.py", line 64, in wrapped_app
    raise exc
  File "C:\Users\kaarelso\AppData\Local\anaconda3\envs\ut-rag\Lib\site-packages\starlette\_exception_handler.py", line 53, in wrapped_app
    await app(scope, receive, sender)
  File "C:\Users\kaarelso\AppData\Local\anaconda3\envs\ut-rag\Lib\site-packages\starlette\routing.py", line 756, in __call__
    await self.middleware_stack(scope, receive, send)
  File "C:\Users\kaarelso\AppData\Local\anaconda3\envs\ut-rag\Lib\site-packages\starlette\routing.py", line 776, in app
    await route.handle(scope, receive, send)
  File "C:\Users\kaarelso\AppData\Local\anaconda3\envs\ut-rag\Lib\site-packages\starlette\routing.py", line 297, in handle
    await self.app(scope, receive, send)
  File "C:\Users\kaarelso\AppData\Local\anaconda3\envs\ut-rag\Lib\site-packages\starlette\routing.py", line 77, in app
    await wrap_app_handling_exceptions(app, request)(scope, receive, send)
  File "C:\Users\kaarelso\AppData\Local\anaconda3\envs\ut-rag\Lib\site-packages\starlette\_exception_handler.py", line 64, in wrapped_app
    raise exc
  File "C:\Users\kaarelso\AppData\Local\anaconda3\envs\ut-rag\Lib\site-packages\starlette\_exception_handler.py", line 53, in wrapped_app
    await app(scope, receive, sender)
  File "C:\Users\kaarelso\AppData\Local\anaconda3\envs\ut-rag\Lib\site-packages\starlette\routing.py", line 72, in app
    response = await func(request)
               ^^^^^^^^^^^^^^^^^^^
  File "C:\Users\kaarelso\AppData\Local\anaconda3\envs\ut-rag\Lib\site-packages\fastapi\routing.py", line 278, in app
    raw_response = await run_endpoint_function(
                   ^^^^^^^^^^^^^^^^^^^^^^^^^^^^
  File "C:\Users\kaarelso\AppData\Local\anaconda3\envs\ut-rag\Lib\site-packages\fastapi\routing.py", line 191, in run_endpoint_function
    return await dependant.call(**values)
           ^^^^^^^^^^^^^^^^^^^^^^^^^^^^^^
  File "C:\Users\kaarelso\AppData\Local\anaconda3\envs\ut-rag\Lib\site-packages\chromadb\telemetry\opentelemetry\__init__.py", line 130, in wrapper
    return await f(*args, **kwargs)
           ^^^^^^^^^^^^^^^^^^^^^^^^
  File "C:\Users\kaarelso\AppData\Local\anaconda3\envs\ut-rag\Lib\site-packages\chromadb\server\fastapi\__init__.py", line 662, in get_collection
    await to_thread.run_sync(
  File "C:\Users\kaarelso\AppData\Local\anaconda3\envs\ut-rag\Lib\site-packages\anyio\to_thread.py", line 56, in run_sync
    return await get_async_backend().run_sync_in_worker_thread(
           ^^^^^^^^^^^^^^^^^^^^^^^^^^^^^^^^^^^^^^^^^^^^^^^^^^^^
  File "C:\Users\kaarelso\AppData\Local\anaconda3\envs\ut-rag\Lib\site-packages\anyio\_backends\_asyncio.py", line 2144, in run_sync_in_worker_thread
    return await future
           ^^^^^^^^^^^^
  File "C:\Users\kaarelso\AppData\Local\anaconda3\envs\ut-rag\Lib\site-packages\anyio\_backends\_asyncio.py", line 851, in run
    result = context.run(func, *args)
             ^^^^^^^^^^^^^^^^^^^^^^^^
  File "C:\Users\kaarelso\AppData\Local\anaconda3\envs\ut-rag\Lib\site-packages\chromadb\telemetry\opentelemetry\__init__.py", line 143, in wrapper
    return f(*args, **kwargs)
           ^^^^^^^^^^^^^^^^^^
  File "C:\Users\kaarelso\AppData\Local\anaconda3\envs\ut-rag\Lib\site-packages\chromadb\api\segment.py", line 270, in get_collection
    raise ValueError(f"Collection {name} does not exist.")
ValueError: Collection docs_collection does not exist.
[32mINFO[0m:     [19-05-2024 17:43:36] ::1:61973 - "GET /api/v1/collections/docs_collection?tenant=default_tenant&database=default_database HTTP/1.1" 500
[32mINFO[0m:     [19-05-2024 17:43:51] ::1:61973 - "POST /api/v1/collections?tenant=default_tenant&database=default_database HTTP/1.1" 200
[32mINFO[0m:     [19-05-2024 17:46:50] Shutting down
[32mINFO[0m:     [19-05-2024 17:46:50] Waiting for application shutdown.
[36mDEBUG[0m:    [19-05-2024 17:46:50] Stopping component System
[36mDEBUG[0m:    [19-05-2024 17:46:50] Stopping component SegmentAPI
[36mDEBUG[0m:    [19-05-2024 17:46:50] Stopping component LocalSegmentManager
[36mDEBUG[0m:    [19-05-2024 17:46:50] Stopping component Posthog
[36mDEBUG[0m:    [19-05-2024 17:46:50] Stopping component QuotaEnforcer
[36mDEBUG[0m:    [19-05-2024 17:46:50] Stopping component SqliteDB
[36mDEBUG[0m:    [19-05-2024 17:46:50] Stopping component OpenTelemetryClient
[32mINFO[0m:     [19-05-2024 17:46:50] Application shutdown complete.
[32mINFO[0m:     [19-05-2024 17:46:50] Finished server process [[36m2708[0m]
